2024-05-28 15:28:57,366 ERROR: Exception on /mentorship/ [GET] [in /opt/anaconda3/lib/python3.11/site-packages/flask/app.py:1744]
Traceback (most recent call last):
  File "/opt/anaconda3/lib/python3.11/site-packages/sqlalchemy/engine/base.py", line 1969, in _exec_single_context
    self.dialect.do_execute(
  File "/opt/anaconda3/lib/python3.11/site-packages/sqlalchemy/engine/default.py", line 922, in do_execute
    cursor.execute(statement, parameters)
sqlite3.OperationalError: no such table: mentorship_mentee

The above exception was the direct cause of the following exception:

Traceback (most recent call last):
  File "/opt/anaconda3/lib/python3.11/site-packages/flask/app.py", line 2529, in wsgi_app
    response = self.full_dispatch_request()
               ^^^^^^^^^^^^^^^^^^^^^^^^^^^^
  File "/opt/anaconda3/lib/python3.11/site-packages/flask/app.py", line 1825, in full_dispatch_request
    rv = self.handle_user_exception(e)
         ^^^^^^^^^^^^^^^^^^^^^^^^^^^^^
  File "/opt/anaconda3/lib/python3.11/site-packages/flask/app.py", line 1823, in full_dispatch_request
    rv = self.dispatch_request()
         ^^^^^^^^^^^^^^^^^^^^^^^
  File "/opt/anaconda3/lib/python3.11/site-packages/flask/app.py", line 1799, in dispatch_request
    return self.ensure_sync(self.view_functions[rule.endpoint])(**view_args)
           ^^^^^^^^^^^^^^^^^^^^^^^^^^^^^^^^^^^^^^^^^^^^^^^^^^^^^^^^^^^^^^^^^
  File "/opt/anaconda3/lib/python3.11/site-packages/flask_login/utils.py", line 290, in decorated_view
    return current_app.ensure_sync(func)(*args, **kwargs)
           ^^^^^^^^^^^^^^^^^^^^^^^^^^^^^^^^^^^^^^^^^^^^^^
  File "/Users/yannoo/Documents/GitHub/SubscriptionWeb/app/views/mentorship.py", line 16, in index
    return render_template('mentorship/index.html', users=users, request_form=request_form, accept_form=accept_form)
           ^^^^^^^^^^^^^^^^^^^^^^^^^^^^^^^^^^^^^^^^^^^^^^^^^^^^^^^^^^^^^^^^^^^^^^^^^^^^^^^^^^^^^^^^^^^^^^^^^^^^^^^^^
  File "/opt/anaconda3/lib/python3.11/site-packages/flask/templating.py", line 147, in render_template
    return _render(app, template, context)
           ^^^^^^^^^^^^^^^^^^^^^^^^^^^^^^^
  File "/opt/anaconda3/lib/python3.11/site-packages/flask/templating.py", line 130, in _render
    rv = template.render(context)
         ^^^^^^^^^^^^^^^^^^^^^^^^
  File "/opt/anaconda3/lib/python3.11/site-packages/jinja2/environment.py", line 1301, in render
    self.environment.handle_exception()
  File "/opt/anaconda3/lib/python3.11/site-packages/jinja2/environment.py", line 936, in handle_exception
    raise rewrite_traceback_stack(source=source)
  File "/Users/yannoo/Documents/GitHub/SubscriptionWeb/app/templates/mentorship/index.html", line 1, in top-level template code
    {% extends 'base.html' %}
  File "/Users/yannoo/Documents/GitHub/SubscriptionWeb/app/templates/base.html", line 66, in top-level template code
    {% block content %}{% endblock %}
    ^^^^^^^^^^^^^^^^^^^^^^^^^
  File "/Users/yannoo/Documents/GitHub/SubscriptionWeb/app/templates/mentorship/index.html", line 30, in block 'content'
    {% for mentee in current_user.pending_mentees %}
    ^^^^^^^^^^^^^^^^^^^^^^^^^
  File "/opt/anaconda3/lib/python3.11/site-packages/sqlalchemy/orm/query.py", line 2833, in __iter__
    result = self._iter()
             ^^^^^^^^^^^^
  File "/opt/anaconda3/lib/python3.11/site-packages/sqlalchemy/orm/dynamic.py", line 171, in _iter
    return self._generate(sess)._iter()
           ^^^^^^^^^^^^^^^^^^^^^^^^^^^^
  File "/opt/anaconda3/lib/python3.11/site-packages/sqlalchemy/orm/query.py", line 2847, in _iter
    result: Union[ScalarResult[_T], Result[_T]] = self.session.execute(
                                                  ^^^^^^^^^^^^^^^^^^^^^
  File "/opt/anaconda3/lib/python3.11/site-packages/sqlalchemy/orm/session.py", line 2308, in execute
    return self._execute_internal(
           ^^^^^^^^^^^^^^^^^^^^^^^
  File "/opt/anaconda3/lib/python3.11/site-packages/sqlalchemy/orm/session.py", line 2190, in _execute_internal
    result: Result[Any] = compile_state_cls.orm_execute_statement(
                          ^^^^^^^^^^^^^^^^^^^^^^^^^^^^^^^^^^^^^^^^
  File "/opt/anaconda3/lib/python3.11/site-packages/sqlalchemy/orm/context.py", line 293, in orm_execute_statement
    result = conn.execute(
             ^^^^^^^^^^^^^
  File "/opt/anaconda3/lib/python3.11/site-packages/sqlalchemy/engine/base.py", line 1416, in execute
    return meth(
           ^^^^^
  File "/opt/anaconda3/lib/python3.11/site-packages/sqlalchemy/sql/elements.py", line 517, in _execute_on_connection
    return connection._execute_clauseelement(
           ^^^^^^^^^^^^^^^^^^^^^^^^^^^^^^^^^^
  File "/opt/anaconda3/lib/python3.11/site-packages/sqlalchemy/engine/base.py", line 1639, in _execute_clauseelement
    ret = self._execute_context(
          ^^^^^^^^^^^^^^^^^^^^^^
  File "/opt/anaconda3/lib/python3.11/site-packages/sqlalchemy/engine/base.py", line 1848, in _execute_context
    return self._exec_single_context(
           ^^^^^^^^^^^^^^^^^^^^^^^^^^
  File "/opt/anaconda3/lib/python3.11/site-packages/sqlalchemy/engine/base.py", line 1988, in _exec_single_context
    self._handle_dbapi_exception(
  File "/opt/anaconda3/lib/python3.11/site-packages/sqlalchemy/engine/base.py", line 2344, in _handle_dbapi_exception
    raise sqlalchemy_exception.with_traceback(exc_info[2]) from e
  File "/opt/anaconda3/lib/python3.11/site-packages/sqlalchemy/engine/base.py", line 1969, in _exec_single_context
    self.dialect.do_execute(
  File "/opt/anaconda3/lib/python3.11/site-packages/sqlalchemy/engine/default.py", line 922, in do_execute
    cursor.execute(statement, parameters)
sqlalchemy.exc.OperationalError: (sqlite3.OperationalError) no such table: mentorship_mentee
[SQL: SELECT user.id AS user_id, user.name AS user_name, user.email AS user_email, user.password AS user_password, user.bio AS user_bio 
FROM user, mentorship_mentee 
WHERE mentorship_mentee.mentor_id = ? AND mentorship_mentee.mentee_id = user.id]
[parameters: (1,)]
(Background on this error at: https://sqlalche.me/e/20/e3q8)
2024-05-28 15:29:20,838 INFO: Application startup [in /Users/yannoo/Documents/GitHub/SubscriptionWeb/app/__init__.py:36]
2024-05-28 15:29:31,288 INFO: Application startup [in /Users/yannoo/Documents/GitHub/SubscriptionWeb/app/__init__.py:36]
2024-05-28 15:29:35,331 INFO: Application startup [in /Users/yannoo/Documents/GitHub/SubscriptionWeb/app/__init__.py:36]
2024-05-28 15:29:35,831 INFO: Application startup [in /Users/yannoo/Documents/GitHub/SubscriptionWeb/app/__init__.py:36]
2024-05-28 15:29:49,529 INFO: Entering login function, request.method=GET [in /Users/yannoo/Documents/GitHub/SubscriptionWeb/app/views/auth.py:11]
2024-05-28 15:29:49,530 INFO: Rendering login template [in /Users/yannoo/Documents/GitHub/SubscriptionWeb/app/views/auth.py:26]
2024-05-28 15:29:51,570 INFO: Entering register function, request.method=GET [in /Users/yannoo/Documents/GitHub/SubscriptionWeb/app/views/auth.py:38]
2024-05-28 15:29:51,570 INFO: Rendering register template [in /Users/yannoo/Documents/GitHub/SubscriptionWeb/app/views/auth.py:58]
2024-05-28 15:30:02,922 INFO: Entering register function, request.method=POST [in /Users/yannoo/Documents/GitHub/SubscriptionWeb/app/views/auth.py:38]
2024-05-28 15:30:03,022 INFO: New user a2@naver.com registered successfully [in /Users/yannoo/Documents/GitHub/SubscriptionWeb/app/views/auth.py:55]
2024-05-28 15:30:03,025 INFO: Entering login function, request.method=GET [in /Users/yannoo/Documents/GitHub/SubscriptionWeb/app/views/auth.py:11]
2024-05-28 15:30:03,025 INFO: Rendering login template [in /Users/yannoo/Documents/GitHub/SubscriptionWeb/app/views/auth.py:26]
2024-05-28 15:30:07,506 INFO: Entering login function, request.method=POST [in /Users/yannoo/Documents/GitHub/SubscriptionWeb/app/views/auth.py:11]
2024-05-28 15:30:07,601 INFO: User a2@naver.com logged in successfully [in /Users/yannoo/Documents/GitHub/SubscriptionWeb/app/views/auth.py:18]
2024-05-28 15:30:23,307 INFO: Entering login function, request.method=GET [in /Users/yannoo/Documents/GitHub/SubscriptionWeb/app/views/auth.py:11]
2024-05-28 15:30:23,308 INFO: Rendering login template [in /Users/yannoo/Documents/GitHub/SubscriptionWeb/app/views/auth.py:26]
2024-05-28 15:30:26,120 INFO: Entering login function, request.method=POST [in /Users/yannoo/Documents/GitHub/SubscriptionWeb/app/views/auth.py:11]
2024-05-28 15:30:26,215 INFO: User a@naver.com logged in successfully [in /Users/yannoo/Documents/GitHub/SubscriptionWeb/app/views/auth.py:18]
2024-05-28 15:32:35,776 INFO: Entering login function, request.method=GET [in /Users/yannoo/Documents/GitHub/SubscriptionWeb/app/views/auth.py:11]
2024-05-28 15:32:35,777 INFO: Rendering login template [in /Users/yannoo/Documents/GitHub/SubscriptionWeb/app/views/auth.py:26]
2024-05-28 15:32:43,525 INFO: Entering login function, request.method=POST [in /Users/yannoo/Documents/GitHub/SubscriptionWeb/app/views/auth.py:11]
2024-05-28 15:32:43,614 INFO: User a2@naver.com logged in successfully [in /Users/yannoo/Documents/GitHub/SubscriptionWeb/app/views/auth.py:18]
2024-05-29 14:21:20,069 INFO: Application startup [in /Users/yannoo/Documents/GitHub/SubscriptionWeb/app/__init__.py:36]
2024-05-29 14:21:20,597 INFO: Application startup [in /Users/yannoo/Documents/GitHub/SubscriptionWeb/app/__init__.py:36]
2024-05-29 14:41:49,781 INFO: Application startup [in /Users/yannoo/Documents/GitHub/SubscriptionWeb/app/__init__.py:36]
2024-05-29 14:41:50,222 INFO: Application startup [in /Users/yannoo/Documents/GitHub/SubscriptionWeb/app/__init__.py:36]
