2024-05-18 21:24:46,476 ERROR: Exception on / [GET] [in /opt/anaconda3/lib/python3.11/site-packages/flask/app.py:1744]
Traceback (most recent call last):
  File "/opt/anaconda3/lib/python3.11/site-packages/flask/app.py", line 2529, in wsgi_app
    response = self.full_dispatch_request()
               ^^^^^^^^^^^^^^^^^^^^^^^^^^^^
  File "/opt/anaconda3/lib/python3.11/site-packages/flask/app.py", line 1825, in full_dispatch_request
    rv = self.handle_user_exception(e)
         ^^^^^^^^^^^^^^^^^^^^^^^^^^^^^
  File "/opt/anaconda3/lib/python3.11/site-packages/flask/app.py", line 1823, in full_dispatch_request
    rv = self.dispatch_request()
         ^^^^^^^^^^^^^^^^^^^^^^^
  File "/opt/anaconda3/lib/python3.11/site-packages/flask/app.py", line 1799, in dispatch_request
    return self.ensure_sync(self.view_functions[rule.endpoint])(**view_args)
           ^^^^^^^^^^^^^^^^^^^^^^^^^^^^^^^^^^^^^^^^^^^^^^^^^^^^^^^^^^^^^^^^^
  File "/Users/yannoo/Documents/GitHub/SubscriptionWeb/app/views/main.py", line 7, in index
    return render_template('index.html')
           ^^^^^^^^^^^^^^^^^^^^^^^^^^^^^
  File "/opt/anaconda3/lib/python3.11/site-packages/flask/templating.py", line 147, in render_template
    return _render(app, template, context)
           ^^^^^^^^^^^^^^^^^^^^^^^^^^^^^^^
  File "/opt/anaconda3/lib/python3.11/site-packages/flask/templating.py", line 130, in _render
    rv = template.render(context)
         ^^^^^^^^^^^^^^^^^^^^^^^^
  File "/opt/anaconda3/lib/python3.11/site-packages/jinja2/environment.py", line 1301, in render
    self.environment.handle_exception()
  File "/opt/anaconda3/lib/python3.11/site-packages/jinja2/environment.py", line 936, in handle_exception
    raise rewrite_traceback_stack(source=source)
  File "/Users/yannoo/Documents/GitHub/SubscriptionWeb/app/templates/index.html", line 1, in top-level template code
    {% extends 'base.html' %}
  File "/Users/yannoo/Documents/GitHub/SubscriptionWeb/app/templates/base.html", line 66, in top-level template code
    {% block content %}{% endblock %}
    ^^^^^^^^^^^^^^^^^^^^^^^^^
  File "/Users/yannoo/Documents/GitHub/SubscriptionWeb/app/templates/index.html", line 11, in block 'content'
    <a class="btn btn-primary btn-lg" href="{{ url_for('courses.course_list') }}" role="button">강의 목록 보기</a>
    ^^^^^^^^^^^^^^^^^^^^^^^^^
  File "/opt/anaconda3/lib/python3.11/site-packages/flask/app.py", line 2034, in url_for
    return self.handle_url_build_error(error, endpoint, values)
           ^^^^^^^^^^^^^^^^^^^^^^^^^^^^^^^^^^^^^^^^^^^^^^^^^^^^
  File "/opt/anaconda3/lib/python3.11/site-packages/flask/app.py", line 2023, in url_for
    rv = url_adapter.build(  # type: ignore[union-attr]
         ^^^^^^^^^^^^^^^^^^^^^^^^^^^^^^^^^^^^^^^^^^^^^^
  File "/opt/anaconda3/lib/python3.11/site-packages/werkzeug/routing/map.py", line 917, in build
    raise BuildError(endpoint, values, method, self)
werkzeug.routing.exceptions.BuildError: Could not build url for endpoint 'courses.course_list'. Did you mean 'community.post_list' instead?
2024-05-18 21:27:21,840 INFO: Application startup [in /Users/yannoo/Documents/GitHub/SubscriptionWeb/app/__init__.py:36]
2024-05-19 00:24:46,400 INFO: Entering register function, request.method=GET [in /Users/yannoo/Documents/GitHub/SubscriptionWeb/app/views/auth.py:38]
2024-05-19 00:24:46,402 INFO: Rendering register template [in /Users/yannoo/Documents/GitHub/SubscriptionWeb/app/views/auth.py:58]
2024-05-19 00:24:57,904 INFO: Entering register function, request.method=POST [in /Users/yannoo/Documents/GitHub/SubscriptionWeb/app/views/auth.py:38]
2024-05-19 00:24:58,001 ERROR: Exception on /auth/register [POST] [in /opt/anaconda3/lib/python3.11/site-packages/flask/app.py:1744]
Traceback (most recent call last):
  File "/opt/anaconda3/lib/python3.11/site-packages/sqlalchemy/engine/base.py", line 1969, in _exec_single_context
    self.dialect.do_execute(
  File "/opt/anaconda3/lib/python3.11/site-packages/sqlalchemy/engine/default.py", line 922, in do_execute
    cursor.execute(statement, parameters)
sqlite3.IntegrityError: NOT NULL constraint failed: user.role

The above exception was the direct cause of the following exception:

Traceback (most recent call last):
  File "/opt/anaconda3/lib/python3.11/site-packages/flask/app.py", line 2529, in wsgi_app
    response = self.full_dispatch_request()
               ^^^^^^^^^^^^^^^^^^^^^^^^^^^^
  File "/opt/anaconda3/lib/python3.11/site-packages/flask/app.py", line 1825, in full_dispatch_request
    rv = self.handle_user_exception(e)
         ^^^^^^^^^^^^^^^^^^^^^^^^^^^^^
  File "/opt/anaconda3/lib/python3.11/site-packages/flask/app.py", line 1823, in full_dispatch_request
    rv = self.dispatch_request()
         ^^^^^^^^^^^^^^^^^^^^^^^
  File "/opt/anaconda3/lib/python3.11/site-packages/flask/app.py", line 1799, in dispatch_request
    return self.ensure_sync(self.view_functions[rule.endpoint])(**view_args)
           ^^^^^^^^^^^^^^^^^^^^^^^^^^^^^^^^^^^^^^^^^^^^^^^^^^^^^^^^^^^^^^^^^
  File "/Users/yannoo/Documents/GitHub/SubscriptionWeb/app/views/auth.py", line 54, in register
    db.session.commit()
  File "/opt/anaconda3/lib/python3.11/site-packages/sqlalchemy/orm/scoping.py", line 598, in commit
    return self._proxied.commit()
           ^^^^^^^^^^^^^^^^^^^^^^
  File "/opt/anaconda3/lib/python3.11/site-packages/sqlalchemy/orm/session.py", line 1969, in commit
    trans.commit(_to_root=True)
  File "<string>", line 2, in commit
  File "/opt/anaconda3/lib/python3.11/site-packages/sqlalchemy/orm/state_changes.py", line 139, in _go
    ret_value = fn(self, *arg, **kw)
                ^^^^^^^^^^^^^^^^^^^^
  File "/opt/anaconda3/lib/python3.11/site-packages/sqlalchemy/orm/session.py", line 1256, in commit
    self._prepare_impl()
  File "<string>", line 2, in _prepare_impl
  File "/opt/anaconda3/lib/python3.11/site-packages/sqlalchemy/orm/state_changes.py", line 139, in _go
    ret_value = fn(self, *arg, **kw)
                ^^^^^^^^^^^^^^^^^^^^
  File "/opt/anaconda3/lib/python3.11/site-packages/sqlalchemy/orm/session.py", line 1231, in _prepare_impl
    self.session.flush()
  File "/opt/anaconda3/lib/python3.11/site-packages/sqlalchemy/orm/session.py", line 4312, in flush
    self._flush(objects)
  File "/opt/anaconda3/lib/python3.11/site-packages/sqlalchemy/orm/session.py", line 4447, in _flush
    with util.safe_reraise():
  File "/opt/anaconda3/lib/python3.11/site-packages/sqlalchemy/util/langhelpers.py", line 146, in __exit__
    raise exc_value.with_traceback(exc_tb)
  File "/opt/anaconda3/lib/python3.11/site-packages/sqlalchemy/orm/session.py", line 4408, in _flush
    flush_context.execute()
  File "/opt/anaconda3/lib/python3.11/site-packages/sqlalchemy/orm/unitofwork.py", line 466, in execute
    rec.execute(self)
  File "/opt/anaconda3/lib/python3.11/site-packages/sqlalchemy/orm/unitofwork.py", line 642, in execute
    util.preloaded.orm_persistence.save_obj(
  File "/opt/anaconda3/lib/python3.11/site-packages/sqlalchemy/orm/persistence.py", line 93, in save_obj
    _emit_insert_statements(
  File "/opt/anaconda3/lib/python3.11/site-packages/sqlalchemy/orm/persistence.py", line 1227, in _emit_insert_statements
    result = connection.execute(
             ^^^^^^^^^^^^^^^^^^^
  File "/opt/anaconda3/lib/python3.11/site-packages/sqlalchemy/engine/base.py", line 1416, in execute
    return meth(
           ^^^^^
  File "/opt/anaconda3/lib/python3.11/site-packages/sqlalchemy/sql/elements.py", line 517, in _execute_on_connection
    return connection._execute_clauseelement(
           ^^^^^^^^^^^^^^^^^^^^^^^^^^^^^^^^^^
  File "/opt/anaconda3/lib/python3.11/site-packages/sqlalchemy/engine/base.py", line 1639, in _execute_clauseelement
    ret = self._execute_context(
          ^^^^^^^^^^^^^^^^^^^^^^
  File "/opt/anaconda3/lib/python3.11/site-packages/sqlalchemy/engine/base.py", line 1848, in _execute_context
    return self._exec_single_context(
           ^^^^^^^^^^^^^^^^^^^^^^^^^^
  File "/opt/anaconda3/lib/python3.11/site-packages/sqlalchemy/engine/base.py", line 1988, in _exec_single_context
    self._handle_dbapi_exception(
  File "/opt/anaconda3/lib/python3.11/site-packages/sqlalchemy/engine/base.py", line 2344, in _handle_dbapi_exception
    raise sqlalchemy_exception.with_traceback(exc_info[2]) from e
  File "/opt/anaconda3/lib/python3.11/site-packages/sqlalchemy/engine/base.py", line 1969, in _exec_single_context
    self.dialect.do_execute(
  File "/opt/anaconda3/lib/python3.11/site-packages/sqlalchemy/engine/default.py", line 922, in do_execute
    cursor.execute(statement, parameters)
sqlalchemy.exc.IntegrityError: (sqlite3.IntegrityError) NOT NULL constraint failed: user.role
[SQL: INSERT INTO user (name, email, password, bio) VALUES (?, ?, ?, ?)]
[parameters: ('회원', 'a@naver.com', 'pbkdf2:sha256:260000$yA7vRZ325ao6tG7M$035918032bfc4ec77ec184621fc0a33bc4b825a57de722fa252a81da9e91abf0', None)]
(Background on this error at: https://sqlalche.me/e/20/gkpj)
2024-05-19 01:21:59,925 INFO: Application startup [in /Users/yannoo/Documents/GitHub/SubscriptionWeb/app/__init__.py:36]
2024-05-19 01:22:06,418 INFO: Application startup [in /Users/yannoo/Documents/GitHub/SubscriptionWeb/app/__init__.py:36]
2024-05-19 01:30:29,739 INFO: Application startup [in /Users/yannoo/Documents/GitHub/SubscriptionWeb/app/__init__.py:36]
2024-05-19 12:07:34,470 INFO: Application startup [in /Users/yannoo/Documents/GitHub/SubscriptionWeb/app/__init__.py:36]
2024-05-19 12:15:44,891 INFO: Application startup [in /Users/yannoo/Documents/GitHub/SubscriptionWeb/app/__init__.py:36]
2024-05-19 12:17:41,296 INFO: Application startup [in /Users/yannoo/Documents/GitHub/SubscriptionWeb/app/__init__.py:36]
2024-05-19 12:17:51,121 INFO: Application startup [in /Users/yannoo/Documents/GitHub/SubscriptionWeb/app/__init__.py:36]
2024-05-19 12:17:56,473 INFO: Application startup [in /Users/yannoo/Documents/GitHub/SubscriptionWeb/app/__init__.py:36]
2024-05-19 12:26:48,500 INFO: Application startup [in /Users/yannoo/Documents/GitHub/SubscriptionWeb/app/__init__.py:36]
