2024-06-11 23:01:25,329 INFO: Application startup [in /Users/yannoo/Documents/GitHub/SubscriptionWeb/app/__init__.py:36]
2024-06-11 23:01:34,953 INFO: Application startup [in /Users/yannoo/Documents/GitHub/SubscriptionWeb/app/__init__.py:36]
2024-06-11 23:04:56,195 ERROR: Exception on /project/detail/3 [GET] [in /Users/yannoo/Documents/GitHub/SubscriptionWeb/instance/venv/lib/python3.12/site-packages/flask/app.py:838]
Traceback (most recent call last):
  File "/Users/yannoo/Documents/GitHub/SubscriptionWeb/instance/venv/lib/python3.12/site-packages/sqlalchemy/engine/base.py", line 1967, in _exec_single_context
    self.dialect.do_execute(
  File "/Users/yannoo/Documents/GitHub/SubscriptionWeb/instance/venv/lib/python3.12/site-packages/sqlalchemy/engine/default.py", line 924, in do_execute
    cursor.execute(statement, parameters)
sqlite3.OperationalError: no such column: project_participant.accepted

The above exception was the direct cause of the following exception:

Traceback (most recent call last):
  File "/Users/yannoo/Documents/GitHub/SubscriptionWeb/instance/venv/lib/python3.12/site-packages/flask/app.py", line 1473, in wsgi_app
    response = self.full_dispatch_request()
               ^^^^^^^^^^^^^^^^^^^^^^^^^^^^
  File "/Users/yannoo/Documents/GitHub/SubscriptionWeb/instance/venv/lib/python3.12/site-packages/flask/app.py", line 882, in full_dispatch_request
    rv = self.handle_user_exception(e)
         ^^^^^^^^^^^^^^^^^^^^^^^^^^^^^
  File "/Users/yannoo/Documents/GitHub/SubscriptionWeb/instance/venv/lib/python3.12/site-packages/flask/app.py", line 880, in full_dispatch_request
    rv = self.dispatch_request()
         ^^^^^^^^^^^^^^^^^^^^^^^
  File "/Users/yannoo/Documents/GitHub/SubscriptionWeb/instance/venv/lib/python3.12/site-packages/flask/app.py", line 865, in dispatch_request
    return self.ensure_sync(self.view_functions[rule.endpoint])(**view_args)  # type: ignore[no-any-return]
           ^^^^^^^^^^^^^^^^^^^^^^^^^^^^^^^^^^^^^^^^^^^^^^^^^^^^^^^^^^^^^^^^^
  File "/Users/yannoo/Documents/GitHub/SubscriptionWeb/instance/venv/lib/python3.12/site-packages/flask_login/utils.py", line 290, in decorated_view
    return current_app.ensure_sync(func)(*args, **kwargs)
           ^^^^^^^^^^^^^^^^^^^^^^^^^^^^^^^^^^^^^^^^^^^^^^
  File "/Users/yannoo/Documents/GitHub/SubscriptionWeb/app/views/project.py", line 91, in detail
    return render_template('project/detail.html', project=project, post_form=post_form, comment_form=comment_form, contribution_form = contribution_form)
           ^^^^^^^^^^^^^^^^^^^^^^^^^^^^^^^^^^^^^^^^^^^^^^^^^^^^^^^^^^^^^^^^^^^^^^^^^^^^^^^^^^^^^^^^^^^^^^^^^^^^^^^^^^^^^^^^^^^^^^^^^^^^^^^^^^^^^^^^^^^^^^
  File "/Users/yannoo/Documents/GitHub/SubscriptionWeb/instance/venv/lib/python3.12/site-packages/flask/templating.py", line 150, in render_template
    return _render(app, template, context)
           ^^^^^^^^^^^^^^^^^^^^^^^^^^^^^^^
  File "/Users/yannoo/Documents/GitHub/SubscriptionWeb/instance/venv/lib/python3.12/site-packages/flask/templating.py", line 131, in _render
    rv = template.render(context)
         ^^^^^^^^^^^^^^^^^^^^^^^^
  File "/Users/yannoo/Documents/GitHub/SubscriptionWeb/instance/venv/lib/python3.12/site-packages/jinja2/environment.py", line 1304, in render
    self.environment.handle_exception()
  File "/Users/yannoo/Documents/GitHub/SubscriptionWeb/instance/venv/lib/python3.12/site-packages/jinja2/environment.py", line 939, in handle_exception
    raise rewrite_traceback_stack(source=source)
  File "/Users/yannoo/Documents/GitHub/SubscriptionWeb/app/templates/project/detail.html", line 1, in top-level template code
    {% extends 'base.html' %}
  File "/Users/yannoo/Documents/GitHub/SubscriptionWeb/app/templates/base.html", line 67, in top-level template code
    {% block content %}{% endblock %}
    ^^^^^^^^^^^^^^^^^^^^^^^^^
  File "/Users/yannoo/Documents/GitHub/SubscriptionWeb/app/templates/project/detail.html", line 9, in block 'content'
    {% set participant = project.project_participants|selectattr('user', 'equalto', current_user)|first %}
    ^^^^^^^^^^^^^^^^^^^^^^^^^
  File "/Users/yannoo/Documents/GitHub/SubscriptionWeb/instance/venv/lib/python3.12/site-packages/jinja2/environment.py", line 487, in getattr
    return getattr(obj, attribute)
           ^^^^^^^^^^^^^^^^^^^^^^^
  File "/Users/yannoo/Documents/GitHub/SubscriptionWeb/instance/venv/lib/python3.12/site-packages/sqlalchemy/orm/attributes.py", line 566, in __get__
    return self.impl.get(state, dict_)  # type: ignore[no-any-return]
           ^^^^^^^^^^^^^^^^^^^^^^^^^^^
  File "/Users/yannoo/Documents/GitHub/SubscriptionWeb/instance/venv/lib/python3.12/site-packages/sqlalchemy/orm/attributes.py", line 1086, in get
    value = self._fire_loader_callables(state, key, passive)
            ^^^^^^^^^^^^^^^^^^^^^^^^^^^^^^^^^^^^^^^^^^^^^^^^
  File "/Users/yannoo/Documents/GitHub/SubscriptionWeb/instance/venv/lib/python3.12/site-packages/sqlalchemy/orm/attributes.py", line 1121, in _fire_loader_callables
    return self.callable_(state, passive)
           ^^^^^^^^^^^^^^^^^^^^^^^^^^^^^^
  File "/Users/yannoo/Documents/GitHub/SubscriptionWeb/instance/venv/lib/python3.12/site-packages/sqlalchemy/orm/strategies.py", line 967, in _load_for_state
    return self._emit_lazyload(
           ^^^^^^^^^^^^^^^^^^^^
  File "/Users/yannoo/Documents/GitHub/SubscriptionWeb/instance/venv/lib/python3.12/site-packages/sqlalchemy/orm/strategies.py", line 1130, in _emit_lazyload
    result = session.execute(
             ^^^^^^^^^^^^^^^^
  File "/Users/yannoo/Documents/GitHub/SubscriptionWeb/instance/venv/lib/python3.12/site-packages/sqlalchemy/orm/session.py", line 2351, in execute
    return self._execute_internal(
           ^^^^^^^^^^^^^^^^^^^^^^^
  File "/Users/yannoo/Documents/GitHub/SubscriptionWeb/instance/venv/lib/python3.12/site-packages/sqlalchemy/orm/session.py", line 2236, in _execute_internal
    result: Result[Any] = compile_state_cls.orm_execute_statement(
                          ^^^^^^^^^^^^^^^^^^^^^^^^^^^^^^^^^^^^^^^^
  File "/Users/yannoo/Documents/GitHub/SubscriptionWeb/instance/venv/lib/python3.12/site-packages/sqlalchemy/orm/context.py", line 293, in orm_execute_statement
    result = conn.execute(
             ^^^^^^^^^^^^^
  File "/Users/yannoo/Documents/GitHub/SubscriptionWeb/instance/venv/lib/python3.12/site-packages/sqlalchemy/engine/base.py", line 1418, in execute
    return meth(
           ^^^^^
  File "/Users/yannoo/Documents/GitHub/SubscriptionWeb/instance/venv/lib/python3.12/site-packages/sqlalchemy/sql/elements.py", line 515, in _execute_on_connection
    return connection._execute_clauseelement(
           ^^^^^^^^^^^^^^^^^^^^^^^^^^^^^^^^^^
  File "/Users/yannoo/Documents/GitHub/SubscriptionWeb/instance/venv/lib/python3.12/site-packages/sqlalchemy/engine/base.py", line 1640, in _execute_clauseelement
    ret = self._execute_context(
          ^^^^^^^^^^^^^^^^^^^^^^
  File "/Users/yannoo/Documents/GitHub/SubscriptionWeb/instance/venv/lib/python3.12/site-packages/sqlalchemy/engine/base.py", line 1846, in _execute_context
    return self._exec_single_context(
           ^^^^^^^^^^^^^^^^^^^^^^^^^^
  File "/Users/yannoo/Documents/GitHub/SubscriptionWeb/instance/venv/lib/python3.12/site-packages/sqlalchemy/engine/base.py", line 1986, in _exec_single_context
    self._handle_dbapi_exception(
  File "/Users/yannoo/Documents/GitHub/SubscriptionWeb/instance/venv/lib/python3.12/site-packages/sqlalchemy/engine/base.py", line 2353, in _handle_dbapi_exception
    raise sqlalchemy_exception.with_traceback(exc_info[2]) from e
  File "/Users/yannoo/Documents/GitHub/SubscriptionWeb/instance/venv/lib/python3.12/site-packages/sqlalchemy/engine/base.py", line 1967, in _exec_single_context
    self.dialect.do_execute(
  File "/Users/yannoo/Documents/GitHub/SubscriptionWeb/instance/venv/lib/python3.12/site-packages/sqlalchemy/engine/default.py", line 924, in do_execute
    cursor.execute(statement, parameters)
sqlalchemy.exc.OperationalError: (sqlite3.OperationalError) no such column: project_participant.accepted
[SQL: SELECT project_participant.id AS project_participant_id, project_participant.user_id AS project_participant_user_id, project_participant.project_id AS project_participant_project_id, project_participant.hours_contributed AS project_participant_hours_contributed, project_participant.accepted AS project_participant_accepted 
FROM project_participant 
WHERE ? = project_participant.project_id]
[parameters: (3,)]
(Background on this error at: https://sqlalche.me/e/20/e3q8)
2024-06-11 23:06:00,091 INFO: Application startup [in /Users/yannoo/Documents/GitHub/SubscriptionWeb/app/__init__.py:36]
2024-06-11 23:06:04,070 INFO: Application startup [in /Users/yannoo/Documents/GitHub/SubscriptionWeb/app/__init__.py:36]
2024-06-11 23:07:00,213 INFO: Application startup [in /Users/yannoo/Documents/GitHub/SubscriptionWeb/app/__init__.py:36]
2024-06-11 23:07:00,511 INFO: Application startup [in /Users/yannoo/Documents/GitHub/SubscriptionWeb/app/__init__.py:36]
2024-06-11 23:08:07,188 INFO: Application startup [in /Users/yannoo/Documents/GitHub/SubscriptionWeb/app/__init__.py:36]
2024-06-11 23:08:07,458 INFO: Application startup [in /Users/yannoo/Documents/GitHub/SubscriptionWeb/app/__init__.py:36]
2024-06-13 23:14:40,451 INFO: Entering login function, request.method=GET [in /Users/yannoo/Documents/GitHub/SubscriptionWeb/app/views/auth.py:11]
2024-06-13 23:14:40,452 INFO: Rendering login template [in /Users/yannoo/Documents/GitHub/SubscriptionWeb/app/views/auth.py:26]
2024-06-13 23:14:45,473 INFO: Entering login function, request.method=POST [in /Users/yannoo/Documents/GitHub/SubscriptionWeb/app/views/auth.py:11]
2024-06-13 23:14:45,636 INFO: User a2@naver.com logged in successfully [in /Users/yannoo/Documents/GitHub/SubscriptionWeb/app/views/auth.py:18]
2024-06-13 23:21:54,642 INFO: Application startup [in /Users/yannoo/Documents/GitHub/SubscriptionWeb/app/__init__.py:36]
2024-06-13 23:21:54,908 INFO: Application startup [in /Users/yannoo/Documents/GitHub/SubscriptionWeb/app/__init__.py:36]
2024-06-13 23:32:22,760 INFO: Application startup [in /Users/yannoo/Documents/GitHub/SubscriptionWeb/app/__init__.py:36]
